<?xml version="1.0"?>
<robot name="adept_model_detailed">
  <link name="base_link">
    <visual>
      <geometry>
        <mesh filename="file:///home/viki/catkin_ws/src/adept_model_detailed/meshes/adept1.dae"/>
      </geometry>
    </visual>
  </link>

<link name="link_one">
    <visual>
      <geometry>
       <mesh filename="file:///home/viki/catkin_ws/src/adept_model_detailed/meshes/adept2.dae"/>
      </geometry>
	<origin rpy="0 0 0" xyz="0.425 0 0"/>
    </visual>
  </link>

<link name="link_two">
    <visual>
      <geometry>
        <mesh filename="file:///home/viki/catkin_ws/src/adept_model_detailed/meshes/adept3.dae"/>
      </geometry>
	<origin rpy="0 0 0" xyz="0.375 0 0"/>
    </visual>
  </link>
<link name="link_four">
    <visual>
      <geometry>
        <mesh filename="file:///home/viki/catkin_ws/src/adept_model_detailed/meshes/adept4.dae"/>
      </geometry>
	<origin rpy="1.57 0 0" xyz="0 0 0.3"/>
    </visual>
  </link>

<joint name="joint_1" type="revolute">
	<parent link="base_link"/>
	<child  link="link_one"/>
	<limit lower="2.6179" upper="-2.6179" effort="30" velocity=".15" />
	<origin xyz="0 0 0"/>
	<axis xyz="0 0 1"/>
</joint>

<joint name="joint_2" type="revolute">
	<parent link="link_one"/>
	<child  link="link_two"/>
	<origin xyz="0.375 0 0"/>
	<axis xyz="0 0 1"/>
	<limit lower="2.5656" upper="-2.5656" effort="30" velocity=".15" />
</joint>
<joint name="joint_3" type="revolute">
	<parent link="link_two"/>
	<child  link="link_four"/>
	<origin xyz="0.375 0 0.3"/>
	<axis xyz="0 0 1"/>
	<limit lower="2.5656" upper="-2.5656" effort="30" velocity=".15" />
</joint>
</robot>
